Workbook

Sheet ebit_12m
B1: EBIT | C1: data real | D1: 45122 | E1: 45153 | F1: 45184
B2: 12M | C2: data cont | D2: 45016 | E2: 45107 | F2: 45107
A4: 3r Petroleum | B4: ON | C4: RRRP3 | D4: 205648000 | E4: 113912000 | F4: 113912000
A5: 3tentos | B5: ON | C5: TTEN3 | D5: 601813000 | E5: 488863000 | F5: 488863000
A6: 521 Particip | B6: ON | C6: QVUM3B
A7: 524 Particip | B7: ON | C7: QVQP3B | D7: -134000 | E7: -134000 | F7: -134000
A8: A P Participacoes | B8: ON | C8: APPA3
A9: A P Participacoes | B9: PN | C9: APPA4
A10: Abc Brasil | B10: ON | C10: ABCB3
A11: Abc Brasil | B11: PN | C11: ABCB4
A12: Abc Brasil | B12: UNT N2 | C12: ABCB11
A13: Abyara | B13: ON | C13: ABYA3
A14: Aco Altona | B14: ON | C14: EALT3 | D14: 53686000 | E14: 50303000 | F14: 50303000
A15: Aco Altona | B15: PN | C15: EALT4 | D15: 53686000 | E15: 50303000 | F15: 50303000
A16: Acos Vill | B16: ON | C16: AVIL3
A17: Acos Vill | B17: PN | C17: AVIL4
A18: Advanced-Dh | B18: ON | C18: ADHM3
A19: Aeris | B19: ON | C19: AERI3 | D19: 254680000 | E19: 277859000 | F19: 277859000
A20: AES Brasil | B20: ON | C20: AESB3 | D20: 767946000 | E20: 848568000 | F20: 848568000
A21: AES Brasil | B21: ON-old | C21: TIET3 | D21: 767946000 | E21: 848568000 | F21: 848568000
A22: AES Brasil | B22: PN | C22: TIET4 | D22: 767946000 | E22: 848568000 | F22: 848568000

Sheet sector_c1
B1: MarketCapitaliz | C1: data real | D1: 45122 | E1: 45153 | F1: 45184
C2: data cont | D2: 45122 | E2: 45153 | F2: 45184
A4: 3r Petroleum | B4: ON | C4: RRRP3 | D4: Petróleo gás e biocombustíveis | E4: Petróleo gás e biocombustíveis | F4: Petróleo gás e biocombustíveis
A5: 3tentos | B5: ON | C5: TTEN3 | D5: Agro | E5: Agro | F5: Agro
A6: 521 Particip | B6: ON | C6: QVUM3B | D6: 0 | E6: 0 | F6: 0
A7: 524 Particip | B7: ON | C7: QVQP3 | D7: 0 | E7: 0 | F7: 0
A8: A P Participacoes | B8: ON | C8: APPA3 | D8: 0 | E8: 0 | F8: 0
A9: A P Participacoes | B9: PN | C9: APPA4 | D9: 0 | E9: 0 | F9: 0
A10: Abc Brasil | B10: ON | C10: ABCB3 | D10: Bancos e Serviços Financeiros | E10: Bancos e Serviços Financeiros | F10: Bancos e Serviços Financeiros
A11: Abc Brasil | B11: PN | C11: ABCB4 | D11: Bancos e Serviços Financeiros | E11: Bancos e Serviços Financeiros | F11: Bancos e Serviços Financeiros
A12: Abc Brasil | B12: UNT N2 | C12: ABCB11 | D12: Bancos e Serviços Financeiros | E12: Bancos e Serviços Financeiros | F12: Bancos e Serviços Financeiros
A13: Abyara | B13: ON | C13: ABYA3 | D13: 0 | E13: 0 | F13: 0
A14: Aco Altona | B14: ON | C14: EALT3 | D14: Indústria | E14: Indústria | F14: Indústria
A15: Aco Altona | B15: PN | C15: EALT4 | D15: Indústria | E15: Indústria | F15: Indústria
A16: Acos Vill | B16: ON | C16: AVIL3 | D16: 0 | E16: 0 | F16: 0
A17: Acos Vill | B17: PN | C17: AVIL4 | D17: 0 | E17: 0 | F17: 0
A18: Advanced-Dh | B18: ON | C18: ADHM3 | D18: Consumo Não-Cíclico | E18: Consumo Não-Cíclico | F18: Consumo Não-Cíclico
A19: Aeris | B19: ON | C19: AERI3 | D19: Indústria | E19: Indústria | F19: Indústria
A20: AES Brasil | B20: ON | C20: AESB3 | D20: Utilidade Pública | E20: Utilidade Pública | F20: Utilidade Pública
A21: AES Brasil | B21: ON-old | C21: TIET3 | D21: Utilidade Pública | E21: Utilidade Pública | F21: Utilidade Pública
A22: AES Brasil | B22: PN | C22: TIET4 | D22: Utilidade Pública | E22: Utilidade Pública | F22: Utilidade Pública

Sheet ir_3m
B1: InfoRatio | C1: data real | D1: 45122 | E1: 45153 | F1: 45184
B2: 3M | C2: data cont | D2: 45016 | E2: 45107 | F2: 45107
A4: 3r Petroleum | B4: ON | C4: RRRP3 | D4: -0.4302905 | E4: -0.60962704 | F4: 0.69189651
A5: 3tentos | B5: ON | C5: TTEN3 | D5: -0.17926532 | E5: 0.78261532 | F5: 2.3164478
A6: 521 Particip | B6: ON | C6: QVUM3B
A7: 524 Particip | B7: ON | C7: QVQP3B
A8: A P Participacoes | B8: ON | C8: APPA3
A9: A P Participacoes | B9: PN | C9: APPA4
A10: Abc Brasil | B10: ON | C10: ABCB3
A11: Abc Brasil | B11: PN | C11: ABCB4 | D11: 0.36039598 | E11: 2.4845142 | F11: 5.7737358
A12: Abc Brasil | B12: UNT N2 | C12: ABCB11
A13: Abyara | B13: ON | C13: ABYA3
A14: Aco Altona | B14: ON | C14: EALT3
A15: Aco Altona | B15: PN | C15: EALT4 | D15: 0.70009563 | E15: 0.14604751 | F15: 0.70552401
A16: Acos Vill | B16: ON | C16: AVIL3
A17: Acos Vill | B17: PN | C17: AVIL4
A18: Advanced-Dh | B18: ON | C18: ADHM3
A19: Aeris | B19: ON | C19: AERI3 | D19: -0.77059577 | E19: -1.9343979 | F19: -1.742498
A20: AES Brasil | B20: ON | C20: AESB3 | D20: 0.7310006 | E20: -3.4132854 | F20: -1.0414439
A21: AES Brasil | B21: ON-old | C21: TIET3
A22: AES Brasil | B22: PN | C22: TIET4

Sheet sharpe
B1: Sharpe | C1: data real | D1: 45122 | E1: 45153 | F1: 45184
B2: 6M | C2: data cont | D2: 45122 | E2: 45153 | F2: 45184
A4: 3r Petroleum | B4: ON | C4: RRRP3 | D4: -0.71723492 | E4: -0.58340749 | F4: 1.0393499
A5: 3tentos | B5: ON | C5: TTEN3 | D5: 2.385826 | E5: -0.17674658 | F5: 0.45434343
A6: 521 Particip | B6: ON | C6: QVUM3B
A7: 524 Particip | B7: ON | C7: QVQP3
A8: A P Participacoes | B8: ON | C8: APPA3
A9: A P Participacoes | B9: PN | C9: APPA4
A10: Abc Brasil | B10: ON | C10: ABCB3
A11: Abc Brasil | B11: PN | C11: ABCB4 | D11: -0.46539838 | E11: -0.027505853 | F11: 1.7853309
A12: Abc Brasil | B12: UNT N2 | C12: ABCB11
A13: Abyara | B13: ON | C13: ABYA3
A14: Aco Altona | B14: ON | C14: EALT3
A15: Aco Altona | B15: PN | C15: EALT4 | D15: 1.2421042 | E15: 1.1868813 | F15: 1.7240063
A16: Acos Vill | B16: ON | C16: AVIL3
A17: Acos Vill | B17: PN | C17: AVIL4
A18: Advanced-Dh | B18: ON | C18: ADHM3
A19: Aeris | B19: ON | C19: AERI3 | D19: -0.071191061 | E19: -0.10539752 | F19: -0.75354202
A20: AES Brasil | B20: ON | C20: AESB3 | D20: 2.0047721 | E20: 0.16494726 | F20: 0.78926
A21: AES Brasil | B21: ON-old | C21: TIET3
A22: AES Brasil | B22: PN | C22: TIET4
D1407: =AVERAGE(D4:D1405) -> 0.72981298 | E1407: =AVERAGE(E4:E1405) -> 0.076461854 | F1407: =AVERAGE(F4:F1405) -> 0.83979142
D1409: =DATE(YEAR(D1),MONTH(D1)-6,15) -> 44941 | E1409: =DATE(YEAR(E1),MONTH(E1)-6,15) -> 44972 | F1409: =DATE(YEAR(F1),MONTH(F1)-6,15) -> 45000

Sheet mkt_cap
B1: MarketCapitaliz | C1: data real | D1: 45122 | E1: 45153 | F1: 45184
C2: data cont | D2: 45122 | E2: 45153 | F2: 45184
A4: 3r Petroleum | B4: ON | C4: RRRP3 | D4: 7.801465e+09 | E4: 7.7918691e+09 | F4: 7.9478024e+09
A5: 3tentos | B5: ON | C5: TTEN3 | D5: 6412001310 | E5: 6446876220 | F5: 7034767560
A6: 521 Particip | B6: ON | C6: QVUM3B
A7: 524 Particip | B7: ON | C7: QVQP3
A8: A P Participacoes | B8: ON | C8: APPA3
A9: A P Participacoes | B9: PN | C9: APPA4
A10: Abc Brasil | B10: ON | C10: ABCB3 | D10: 4.013099e+09 | E10: 4.1713621e+09 | F10: 4689108392
A11: Abc Brasil | B11: PN | C11: ABCB4 | D11: 4.013099e+09 | E11: 4.1713621e+09 | F11: 4689108392
A12: Abc Brasil | B12: UNT N2 | C12: ABCB11 | D12: 4.013099e+09 | E12: 4.1713621e+09 | F12: 4689108392
A13: Abyara | B13: ON | C13: ABYA3
A14: Aco Altona | B14: ON | C14: EALT3 | D14: 183817500 | E14: 180345000 | F14: 196417500
A15: Aco Altona | B15: PN | C15: EALT4 | D15: 183817500 | E15: 180345000 | F15: 196417500
A16: Acos Vill | B16: ON | C16: AVIL3
A17: Acos Vill | B17: PN | C17: AVIL4
A18: Advanced-Dh | B18: ON | C18: ADHM3
A19: Aeris | B19: ON | C19: AERI3 | D19: 9.1230552e+08 | E19: 8.5996012e+08 | F19: 6.9544601e+08
A20: AES Brasil | B20: ON | C20: AESB3 | D20: 7.1027423e+09 | E20: 6.4767379e+09 | F20: 6.9883761e+09
A21: AES Brasil | B21: ON-old | C21: TIET3 | D21: 7.1027423e+09 | E21: 6.4767379e+09 | F21: 6.9883761e+09
A22: AES Brasil | B22: PN | C22: TIET4 | D22: 7.1027423e+09 | E22: 6.4767379e+09 | F22: 6.9883761e+09

Sheet calc_panel
B1: id | C1: tickers | D1: dates | E1: ebit_12m | F1: ir_3m | G1: sharpe | H1: mkt_cap | I1: sector_c1
B2: =CONCATENATE(C2,"-",K2,"-0",L2,"-",M2) -> RRRP3-2023-07-15 | C2: =ir_3m!C4 -> RRRP3 | D2: 45122 | E2: =IF(OFFSET(ebit_12m!$D$4,$A2,0)="","",OFFSET(ebit_12m!$D$4,$A2,0)) -> 205648000 | F2: =IF(OFFSET(ir_3m!$D$4,$A2,0)="","",OFFSET(ir_3m!$D$4,$A2,0)) -> -0.4302905 | G2: =IF(OFFSET(sharpe!$D$4,$A2,0)="","",OFFSET(sharpe!$D$4,$A2,0)) -> -0.71723492 | H2: =IF(OFFSET(mkt_cap!$D$4,$A2,0)="","",OFFSET(mkt_cap!$D$4,$A2,0)) -> 7.801465e+09 | I2: =IF(OFFSET(sector_c1!$D$4,$A2,0)="","",OFFSET(sector_c1!$D$4,$A2,0)) -> Petróleo gás e biocombustíveis | K2: =YEAR(D2) -> 2023 | L2: =MONTH(D2) -> 7 | M2: =DAY(D2) -> 15
B3: =CONCATENATE(C3,"-",K3,"-0",L3,"-",M3) -> RRRP3-2023-08-15 | C3: =ir_3m!C4 -> RRRP3 | D3: 45153 | E3: =IF(OFFSET(ebit_12m!$E$4,$A2,0)="","",OFFSET(ebit_12m!$E$4,$A2,0)) -> 113912000 | F3: =IF(OFFSET(ir_3m!$E$4,$A2,0)="","",OFFSET(ir_3m!$E$4,$A2,0)) -> -0.60962704 | G3: =IF(OFFSET(sharpe!$E$4,$A2,0)="","",OFFSET(sharpe!$E$4,$A2,0)) -> -0.58340749 | H3: =IF(OFFSET(mkt_cap!$E$4,$A2,0)="","",OFFSET(mkt_cap!$E$4,$A2,0)) -> 7.7918691e+09 | I3: =IF(OFFSET(sector_c1!$D$4,$A3,0)="","",OFFSET(sector_c1!$D$4,$A3,0)) -> Petróleo gás e biocombustíveis | K3: =YEAR(D3) -> 2023 | L3: =MONTH(D3) -> 8 | M3: =DAY(D3) -> 15
B4: =CONCATENATE(C4,"-",K4,"-0",L4,"-",M4) -> RRRP3-2023-09-15 | C4: =ir_3m!C4 -> RRRP3 | D4: 45184 | E4: =IF(OFFSET(ebit_12m!$F$4,$A2,0)="","",OFFSET(ebit_12m!$F$4,$A2,0)) -> 113912000 | F4: =IF(OFFSET(ir_3m!$F$4,$A2,0)="","",OFFSET(ir_3m!$F$4,$A2,0)) -> 0.69189651 | G4: =IF(OFFSET(sharpe!$F$4,$A2,0)="","",OFFSET(sharpe!$F$4,$A2,0)) -> 1.0393499 | H4: =IF(OFFSET(mkt_cap!$F$4,$A2,0)="","",OFFSET(mkt_cap!$F$4,$A2,0)) -> 7.9478024e+09 | I4: =IF(OFFSET(sector_c1!$D$4,$A4,0)="","",OFFSET(sector_c1!$D$4,$A4,0)) -> Petróleo gás e biocombustíveis | K4: =YEAR(D4) -> 2023 | L4: =MONTH(D4) -> 9 | M4: =DAY(D4) -> 15
A5: 1 | B5: =CONCATENATE(C5,"-",K5,"-0",L5,"-",M5) -> TTEN3-2023-07-15 | C5: =OFFSET(ir_3m!$C$4,calc_panel!A5,0) -> TTEN3 | D5: 45122 | E5: =IF(OFFSET(ebit_12m!$D$4,$A5,0)="","",OFFSET(ebit_12m!$D$4,$A5,0)) -> 601813000 | F5: =IF(OFFSET(ir_3m!$D$4,$A5,0)="","",OFFSET(ir_3m!$D$4,$A5,0)) -> -0.17926532 | G5: =IF(OFFSET(sharpe!$D$4,$A5,0)="","",OFFSET(sharpe!$D$4,$A5,0)) -> 2.385826 | H5: =IF(OFFSET(mkt_cap!$D$4,$A5,0)="","",OFFSET(mkt_cap!$D$4,$A5,0)) -> 6412001310 | I5: =IF(OFFSET(sector_c1!$D$4,$A5,0)="","",OFFSET(sector_c1!$D$4,$A5,0)) -> Agro | K5: =YEAR(D5) -> 2023 | L5: =MONTH(D5) -> 7 | M5: =DAY(D5) -> 15
A6: 1 | B6: =CONCATENATE(C6,"-",K6,"-0",L6,"-",M6) -> TTEN3-2023-08-15 | C6: =OFFSET(ir_3m!$C$4,calc_panel!A6,0) -> TTEN3 | D6: 45153 | E6: =IF(OFFSET(ebit_12m!$E$4,$A5,0)="","",OFFSET(ebit_12m!$E$4,$A5,0)) -> 488863000 | F6: =IF(OFFSET(ir_3m!$E$4,$A5,0)="","",OFFSET(ir_3m!$E$4,$A5,0)) -> 0.78261532 | G6: =IF(OFFSET(sharpe!$E$4,$A5,0)="","",OFFSET(sharpe!$E$4,$A5,0)) -> -0.17674658 | H6: =IF(OFFSET(mkt_cap!$E$4,$A5,0)="","",OFFSET(mkt_cap!$E$4,$A5,0)) -> 6446876220 | I6: =IF(OFFSET(sector_c1!$D$4,$A6,0)="","",OFFSET(sector_c1!$D$4,$A6,0)) -> Agro | K6: =YEAR(D6) -> 2023 | L6: =MONTH(D6) -> 8 | M6: =DAY(D6) -> 15
A7: 1 | B7: =CONCATENATE(C7,"-",K7,"-0",L7,"-",M7) -> TTEN3-2023-09-15 | C7: =OFFSET(ir_3m!$C$4,calc_panel!A7,0) -> TTEN3 | D7: 45184 | E7: =IF(OFFSET(ebit_12m!$F$4,$A5,0)="","",OFFSET(ebit_12m!$F$4,$A5,0)) -> 488863000 | F7: =IF(OFFSET(ir_3m!$F$4,$A5,0)="","",OFFSET(ir_3m!$F$4,$A5,0)) -> 2.3164478 | G7: =IF(OFFSET(sharpe!$F$4,$A5,0)="","",OFFSET(sharpe!$F$4,$A5,0)) -> 0.45434343 | H7: =IF(OFFSET(mkt_cap!$F$4,$A5,0)="","",OFFSET(mkt_cap!$F$4,$A5,0)) -> 7034767560 | I7: =IF(OFFSET(sector_c1!$D$4,$A7,0)="","",OFFSET(sector_c1!$D$4,$A7,0)) -> Agro | K7: =YEAR(D7) -> 2023 | L7: =MONTH(D7) -> 9 | M7: =DAY(D7) -> 15
A8: =A5+1 -> 2 | B8: =CONCATENATE(C8,"-",K8,"-0",L8,"-",M8) -> QVUM3B-2023-07-15 | C8: =OFFSET(ir_3m!$C$4,calc_panel!A8,0) -> QVUM3B | D8: 45122 | E8: =IF(OFFSET(ebit_12m!$D$4,$A8,0)="","",OFFSET(ebit_12m!$D$4,$A8,0)) | F8: =IF(OFFSET(ir_3m!$D$4,$A8,0)="","",OFFSET(ir_3m!$D$4,$A8,0)) | G8: =IF(OFFSET(sharpe!$D$4,$A8,0)="","",OFFSET(sharpe!$D$4,$A8,0)) | H8: =IF(OFFSET(mkt_cap!$D$4,$A8,0)="","",OFFSET(mkt_cap!$D$4,$A8,0)) | I8: =IF(OFFSET(sector_c1!$D$4,$A8,0)="","",OFFSET(sector_c1!$D$4,$A8,0)) -> 0 | K8: =YEAR(D8) -> 2023 | L8: =MONTH(D8) -> 7 | M8: =DAY(D8) -> 15
A9: =A6+1 -> 2 | B9: =CONCATENATE(C9,"-",K9,"-0",L9,"-",M9) -> QVUM3B-2023-08-15 | C9: =OFFSET(ir_3m!$C$4,calc_panel!A9,0) -> QVUM3B | D9: 45153 | E9: =IF(OFFSET(ebit_12m!$E$4,$A8,0)="","",OFFSET(ebit_12m!$E$4,$A8,0)) | F9: =IF(OFFSET(ir_3m!$E$4,$A8,0)="","",OFFSET(ir_3m!$E$4,$A8,0)) | G9: =IF(OFFSET(sharpe!$E$4,$A8,0)="","",OFFSET(sharpe!$E$4,$A8,0)) | H9: =IF(OFFSET(mkt_cap!$E$4,$A8,0)="","",OFFSET(mkt_cap!$E$4,$A8,0)) | I9: =IF(OFFSET(sector_c1!$D$4,$A9,0)="","",OFFSET(sector_c1!$D$4,$A9,0)) -> 0 | K9: =YEAR(D9) -> 2023 | L9: =MONTH(D9) -> 8 | M9: =DAY(D9) -> 15
A10: =A7+1 -> 2 | B10: =CONCATENATE(C10,"-",K10,"-0",L10,"-",M10) -> QVUM3B-2023-09-15 | C10: =OFFSET(ir_3m!$C$4,calc_panel!A10,0) -> QVUM3B | D10: 45184 | E10: =IF(OFFSET(ebit_12m!$F$4,$A8,0)="","",OFFSET(ebit_12m!$F$4,$A8,0)) | F10: =IF(OFFSET(ir_3m!$F$4,$A8,0)="","",OFFSET(ir_3m!$F$4,$A8,0)) | G10: =IF(OFFSET(sharpe!$F$4,$A8,0)="","",OFFSET(sharpe!$F$4,$A8,0)) | H10: =IF(OFFSET(mkt_cap!$F$4,$A8,0)="","",OFFSET(mkt_cap!$F$4,$A8,0)) | I10: =IF(OFFSET(sector_c1!$D$4,$A10,0)="","",OFFSET(sector_c1!$D$4,$A10,0)) -> 0 | K10: =YEAR(D10) -> 2023 | L10: =MONTH(D10) -> 9 | M10: =DAY(D10) -> 15
A11: =A8+1 -> 3 | B11: =CONCATENATE(C11,"-",K11,"-0",L11,"-",M11) -> QVQP3B-2023-07-15 | C11: =OFFSET(ir_3m!$C$4,calc_panel!A11,0) -> QVQP3B | D11: =D2 -> 45122 | E11: =IF(OFFSET(ebit_12m!$D$4,$A11,0)="","",OFFSET(ebit_12m!$D$4,$A11,0)) -> -134000 | F11: =IF(OFFSET(ir_3m!$D$4,$A11,0)="","",OFFSET(ir_3m!$D$4,$A11,0)) | G11: =IF(OFFSET(sharpe!$D$4,$A11,0)="","",OFFSET(sharpe!$D$4,$A11,0)) | H11: =IF(OFFSET(mkt_cap!$D$4,$A11,0)="","",OFFSET(mkt_cap!$D$4,$A11,0)) | I11: =IF(OFFSET(sector_c1!$D$4,$A11,0)="","",OFFSET(sector_c1!$D$4,$A11,0)) -> 0 | K11: =YEAR(D11) -> 2023 | L11: =MONTH(D11) -> 7 | M11: =DAY(D11) -> 15
A12: =A9+1 -> 3 | B12: =CONCATENATE(C12,"-",K12,"-0",L12,"-",M12) -> QVQP3B-2023-08-15 | C12: =OFFSET(ir_3m!$C$4,calc_panel!A12,0) -> QVQP3B | D12: =D3 -> 45153 | E12: =IF(OFFSET(ebit_12m!$E$4,$A11,0)="","",OFFSET(ebit_12m!$E$4,$A11,0)) -> -134000 | F12: =IF(OFFSET(ir_3m!$E$4,$A11,0)="","",OFFSET(ir_3m!$E$4,$A11,0)) | G12: =IF(OFFSET(sharpe!$E$4,$A11,0)="","",OFFSET(sharpe!$E$4,$A11,0)) | H12: =IF(OFFSET(mkt_cap!$E$4,$A11,0)="","",OFFSET(mkt_cap!$E$4,$A11,0)) | I12: =IF(OFFSET(sector_c1!$D$4,$A12,0)="","",OFFSET(sector_c1!$D$4,$A12,0)) -> 0 | K12: =YEAR(D12) -> 2023 | L12: =MONTH(D12) -> 8 | M12: =DAY(D12) -> 15
A13: =A10+1 -> 3 | B13: =CONCATENATE(C13,"-",K13,"-0",L13,"-",M13) -> QVQP3B-2023-09-15 | C13: =OFFSET(ir_3m!$C$4,calc_panel!A13,0) -> QVQP3B | D13: =D4 -> 45184 | E13: =IF(OFFSET(ebit_12m!$F$4,$A11,0)="","",OFFSET(ebit_12m!$F$4,$A11,0)) -> -134000 | F13: =IF(OFFSET(ir_3m!$F$4,$A11,0)="","",OFFSET(ir_3m!$F$4,$A11,0)) | G13: =IF(OFFSET(sharpe!$F$4,$A11,0)="","",OFFSET(sharpe!$F$4,$A11,0)) | H13: =IF(OFFSET(mkt_cap!$F$4,$A11,0)="","",OFFSET(mkt_cap!$F$4,$A11,0)) | I13: =IF(OFFSET(sector_c1!$D$4,$A13,0)="","",OFFSET(sector_c1!$D$4,$A13,0)) -> 0 | K13: =YEAR(D13) -> 2023 | L13: =MONTH(D13) -> 9 | M13: =DAY(D13) -> 15
A14: =A11+1 -> 4 | B14: =CONCATENATE(C14,"-",K14,"-0",L14,"-",M14) -> APPA3-2023-07-15 | C14: =OFFSET(ir_3m!$C$4,calc_panel!A14,0) -> APPA3 | D14: =D11 -> 45122 | E14: =IF(OFFSET(ebit_12m!$D$4,$A14,0)="","",OFFSET(ebit_12m!$D$4,$A14,0)) | F14: =IF(OFFSET(ir_3m!$D$4,$A14,0)="","",OFFSET(ir_3m!$D$4,$A14,0)) | G14: =IF(OFFSET(sharpe!$D$4,$A14,0)="","",OFFSET(sharpe!$D$4,$A14,0)) | H14: =IF(OFFSET(mkt_cap!$D$4,$A14,0)="","",OFFSET(mkt_cap!$D$4,$A14,0)) | I14: =IF(OFFSET(sector_c1!$D$4,$A14,0)="","",OFFSET(sector_c1!$D$4,$A14,0)) -> 0 | K14: =YEAR(D14) -> 2023 | L14: =MONTH(D14) -> 7 | M14: =DAY(D14) -> 15
A15: =A12+1 -> 4 | B15: =CONCATENATE(C15,"-",K15,"-0",L15,"-",M15) -> APPA3-2023-08-15 | C15: =OFFSET(ir_3m!$C$4,calc_panel!A15,0) -> APPA3 | D15: =D12 -> 45153 | E15: =IF(OFFSET(ebit_12m!$E$4,$A14,0)="","",OFFSET(ebit_12m!$E$4,$A14,0)) | F15: =IF(OFFSET(ir_3m!$E$4,$A14,0)="","",OFFSET(ir_3m!$E$4,$A14,0)) | G15: =IF(OFFSET(sharpe!$E$4,$A14,0)="","",OFFSET(sharpe!$E$4,$A14,0)) | H15: =IF(OFFSET(mkt_cap!$E$4,$A14,0)="","",OFFSET(mkt_cap!$E$4,$A14,0)) | I15: =IF(OFFSET(sector_c1!$D$4,$A15,0)="","",OFFSET(sector_c1!$D$4,$A15,0)) -> 0 | K15: =YEAR(D15) -> 2023 | L15: =MONTH(D15) -> 8 | M15: =DAY(D15) -> 15
A16: =A13+1 -> 4 | B16: =CONCATENATE(C16,"-",K16,"-0",L16,"-",M16) -> APPA3-2023-09-15 | C16: =OFFSET(ir_3m!$C$4,calc_panel!A16,0) -> APPA3 | D16: =D13 -> 45184 | E16: =IF(OFFSET(ebit_12m!$F$4,$A14,0)="","",OFFSET(ebit_12m!$F$4,$A14,0)) | F16: =IF(OFFSET(ir_3m!$F$4,$A14,0)="","",OFFSET(ir_3m!$F$4,$A14,0)) | G16: =IF(OFFSET(sharpe!$F$4,$A14,0)="","",OFFSET(sharpe!$F$4,$A14,0)) | H16: =IF(OFFSET(mkt_cap!$F$4,$A14,0)="","",OFFSET(mkt_cap!$F$4,$A14,0)) | I16: =IF(OFFSET(sector_c1!$D$4,$A16,0)="","",OFFSET(sector_c1!$D$4,$A16,0)) -> 0 | K16: =YEAR(D16) -> 2023 | L16: =MONTH(D16) -> 9 | M16: =DAY(D16) -> 15
A17: =A14+1 -> 5 | B17: =CONCATENATE(C17,"-",K17,"-0",L17,"-",M17) -> APPA4-2023-07-15 | C17: =OFFSET(ir_3m!$C$4,calc_panel!A17,0) -> APPA4 | D17: =D14 -> 45122 | E17: =IF(OFFSET(ebit_12m!$D$4,$A17,0)="","",OFFSET(ebit_12m!$D$4,$A17,0)) | F17: =IF(OFFSET(ir_3m!$D$4,$A17,0)="","",OFFSET(ir_3m!$D$4,$A17,0)) | G17: =IF(OFFSET(sharpe!$D$4,$A17,0)="","",OFFSET(sharpe!$D$4,$A17,0)) | H17: =IF(OFFSET(mkt_cap!$D$4,$A17,0)="","",OFFSET(mkt_cap!$D$4,$A17,0)) | I17: =IF(OFFSET(sector_c1!$D$4,$A17,0)="","",OFFSET(sector_c1!$D$4,$A17,0)) -> 0 | K17: =YEAR(D17) -> 2023 | L17: =MONTH(D17) -> 7 | M17: =DAY(D17) -> 15
A18: =A15+1 -> 5 | B18: =CONCATENATE(C18,"-",K18,"-0",L18,"-",M18) -> APPA4-2023-08-15 | C18: =OFFSET(ir_3m!$C$4,calc_panel!A18,0) -> APPA4 | D18: =D15 -> 45153 | E18: =IF(OFFSET(ebit_12m!$E$4,$A17,0)="","",OFFSET(ebit_12m!$E$4,$A17,0)) | F18: =IF(OFFSET(ir_3m!$E$4,$A17,0)="","",OFFSET(ir_3m!$E$4,$A17,0)) | G18: =IF(OFFSET(sharpe!$E$4,$A17,0)="","",OFFSET(sharpe!$E$4,$A17,0)) | H18: =IF(OFFSET(mkt_cap!$E$4,$A17,0)="","",OFFSET(mkt_cap!$E$4,$A17,0)) | I18: =IF(OFFSET(sector_c1!$D$4,$A18,0)="","",OFFSET(sector_c1!$D$4,$A18,0)) -> 0 | K18: =YEAR(D18) -> 2023 | L18: =MONTH(D18) -> 8 | M18: =DAY(D18) -> 15
A19: =A16+1 -> 5 | B19: =CONCATENATE(C19,"-",K19,"-0",L19,"-",M19) -> APPA4-2023-09-15 | C19: =OFFSET(ir_3m!$C$4,calc_panel!A19,0) -> APPA4 | D19: =D16 -> 45184 | E19: =IF(OFFSET(ebit_12m!$F$4,$A17,0)="","",OFFSET(ebit_12m!$F$4,$A17,0)) | F19: =IF(OFFSET(ir_3m!$F$4,$A17,0)="","",OFFSET(ir_3m!$F$4,$A17,0)) | G19: =IF(OFFSET(sharpe!$F$4,$A17,0)="","",OFFSET(sharpe!$F$4,$A17,0)) | H19: =IF(OFFSET(mkt_cap!$F$4,$A17,0)="","",OFFSET(mkt_cap!$F$4,$A17,0)) | I19: =IF(OFFSET(sector_c1!$D$4,$A19,0)="","",OFFSET(sector_c1!$D$4,$A19,0)) -> 0 | K19: =YEAR(D19) -> 2023 | L19: =MONTH(D19) -> 9 | M19: =DAY(D19) -> 15
A20: =A17+1 -> 6 | B20: =CONCATENATE(C20,"-",K20,"-0",L20,"-",M20) -> ABCB3-2023-07-15 | C20: =OFFSET(ir_3m!$C$4,calc_panel!A20,0) -> ABCB3 | D20: =D17 -> 45122 | E20: =IF(OFFSET(ebit_12m!$D$4,$A20,0)="","",OFFSET(ebit_12m!$D$4,$A20,0)) | F20: =IF(OFFSET(ir_3m!$D$4,$A20,0)="","",OFFSET(ir_3m!$D$4,$A20,0)) | G20: =IF(OFFSET(sharpe!$D$4,$A20,0)="","",OFFSET(sharpe!$D$4,$A20,0)) | H20: =IF(OFFSET(mkt_cap!$D$4,$A20,0)="","",OFFSET(mkt_cap!$D$4,$A20,0)) -> 4.013099e+09 | I20: =IF(OFFSET(sector_c1!$D$4,$A20,0)="","",OFFSET(sector_c1!$D$4,$A20,0)) -> Bancos e Serviços Financeiros | K20: =YEAR(D20) -> 2023 | L20: =MONTH(D20) -> 7 | M20: =DAY(D20) -> 15
A21: =A18+1 -> 6 | B21: =CONCATENATE(C21,"-",K21,"-0",L21,"-",M21) -> ABCB3-2023-08-15 | C21: =OFFSET(ir_3m!$C$4,calc_panel!A21,0) -> ABCB3 | D21: =D18 -> 45153 | E21: =IF(OFFSET(ebit_12m!$E$4,$A20,0)="","",OFFSET(ebit_12m!$E$4,$A20,0)) | F21: =IF(OFFSET(ir_3m!$E$4,$A20,0)="","",OFFSET(ir_3m!$E$4,$A20,0)) | G21: =IF(OFFSET(sharpe!$E$4,$A20,0)="","",OFFSET(sharpe!$E$4,$A20,0)) | H21: =IF(OFFSET(mkt_cap!$E$4,$A20,0)="","",OFFSET(mkt_cap!$E$4,$A20,0)) -> 4.1713621e+09 | I21: =IF(OFFSET(sector_c1!$D$4,$A21,0)="","",OFFSET(sector_c1!$D$4,$A21,0)) -> Bancos e Serviços Financeiros | K21: =YEAR(D21) -> 2023 | L21: =MONTH(D21) -> 8 | M21: =DAY(D21) -> 15
A22: =A19+1 -> 6 | B22: =CONCATENATE(C22,"-",K22,"-0",L22,"-",M22) -> ABCB3-2023-09-15 | C22: =OFFSET(ir_3m!$C$4,calc_panel!A22,0) -> ABCB3 | D22: =D19 -> 45184 | E22: =IF(OFFSET(ebit_12m!$F$4,$A20,0)="","",OFFSET(ebit_12m!$F$4,$A20,0)) | F22: =IF(OFFSET(ir_3m!$F$4,$A20,0)="","",OFFSET(ir_3m!$F$4,$A20,0)) | G22: =IF(OFFSET(sharpe!$F$4,$A20,0)="","",OFFSET(sharpe!$F$4,$A20,0)) | H22: =IF(OFFSET(mkt_cap!$F$4,$A20,0)="","",OFFSET(mkt_cap!$F$4,$A20,0)) -> 4689108392 | I22: =IF(OFFSET(sector_c1!$D$4,$A22,0)="","",OFFSET(sector_c1!$D$4,$A22,0)) -> Bancos e Serviços Financeiros | K22: =YEAR(D22) -> 2023 | L22: =MONTH(D22) -> 9 | M22: =DAY(D22) -> 15
A23: =A20+1 -> 7 | B23: =CONCATENATE(C23,"-",K23,"-0",L23,"-",M23) -> ABCB4-2023-07-15 | C23: =OFFSET(ir_3m!$C$4,calc_panel!A23,0) -> ABCB4 | D23: =D20 -> 45122 | E23: =IF(OFFSET(ebit_12m!$D$4,$A23,0)="","",OFFSET(ebit_12m!$D$4,$A23,0)) | F23: =IF(OFFSET(ir_3m!$D$4,$A23,0)="","",OFFSET(ir_3m!$D$4,$A23,0)) -> 0.36039598 | G23: =IF(OFFSET(sharpe!$D$4,$A23,0)="","",OFFSET(sharpe!$D$4,$A23,0)) -> -0.46539838 | H23: =IF(OFFSET(mkt_cap!$D$4,$A23,0)="","",OFFSET(mkt_cap!$D$4,$A23,0)) -> 4.013099e+09 | I23: =IF(OFFSET(sector_c1!$D$4,$A23,0)="","",OFFSET(sector_c1!$D$4,$A23,0)) -> Bancos e Serviços Financeiros | K23: =YEAR(D23) -> 2023 | L23: =MONTH(D23) -> 7 | M23: =DAY(D23) -> 15
A24: =A21+1 -> 7 | B24: =CONCATENATE(C24,"-",K24,"-0",L24,"-",M24) -> ABCB4-2023-08-15 | C24: =OFFSET(ir_3m!$C$4,calc_panel!A24,0) -> ABCB4 | D24: =D21 -> 45153 | E24: =IF(OFFSET(ebit_12m!$E$4,$A23,0)="","",OFFSET(ebit_12m!$E$4,$A23,0)) | F24: =IF(OFFSET(ir_3m!$E$4,$A23,0)="","",OFFSET(ir_3m!$E$4,$A23,0)) -> 2.4845142 | G24: =IF(OFFSET(sharpe!$E$4,$A23,0)="","",OFFSET(sharpe!$E$4,$A23,0)) -> -0.027505853 | H24: =IF(OFFSET(mkt_cap!$E$4,$A23,0)="","",OFFSET(mkt_cap!$E$4,$A23,0)) -> 4.1713621e+09 | I24: =IF(OFFSET(sector_c1!$D$4,$A24,0)="","",OFFSET(sector_c1!$D$4,$A24,0)) -> Bancos e Serviços Financeiros | K24: =YEAR(D24) -> 2023 | L24: =MONTH(D24) -> 8 | M24: =DAY(D24) -> 15
A25: =A22+1 -> 7 | B25: =CONCATENATE(C25,"-",K25,"-0",L25,"-",M25) -> ABCB4-2023-09-15 | C25: =OFFSET(ir_3m!$C$4,calc_panel!A25,0) -> ABCB4 | D25: =D22 -> 45184 | E25: =IF(OFFSET(ebit_12m!$F$4,$A23,0)="","",OFFSET(ebit_12m!$F$4,$A23,0)) | F25: =IF(OFFSET(ir_3m!$F$4,$A23,0)="","",OFFSET(ir_3m!$F$4,$A23,0)) -> 5.7737358 | G25: =IF(OFFSET(sharpe!$F$4,$A23,0)="","",OFFSET(sharpe!$F$4,$A23,0)) -> 1.7853309 | H25: =IF(OFFSET(mkt_cap!$F$4,$A23,0)="","",OFFSET(mkt_cap!$F$4,$A23,0)) -> 4689108392 | I25: =IF(OFFSET(sector_c1!$D$4,$A25,0)="","",OFFSET(sector_c1!$D$4,$A25,0)) -> Bancos e Serviços Financeiros | K25: =YEAR(D25) -> 2023 | L25: =MONTH(D25) -> 9 | M25: =DAY(D25) -> 15
A26: =A23+1 -> 8 | B26: =CONCATENATE(C26,"-",K26,"-0",L26,"-",M26) -> ABCB11-2023-07-15 | C26: =OFFSET(ir_3m!$C$4,calc_panel!A26,0) -> ABCB11 | D26: =D23 -> 45122 | E26: =IF(OFFSET(ebit_12m!$D$4,$A26,0)="","",OFFSET(ebit_12m!$D$4,$A26,0)) | F26: =IF(OFFSET(ir_3m!$D$4,$A26,0)="","",OFFSET(ir_3m!$D$4,$A26,0)) | G26: =IF(OFFSET(sharpe!$D$4,$A26,0)="","",OFFSET(sharpe!$D$4,$A26,0)) | H26: =IF(OFFSET(mkt_cap!$D$4,$A26,0)="","",OFFSET(mkt_cap!$D$4,$A26,0)) -> 4.013099e+09 | I26: =IF(OFFSET(sector_c1!$D$4,$A26,0)="","",OFFSET(sector_c1!$D$4,$A26,0)) -> Bancos e Serviços Financeiros | K26: =YEAR(D26) -> 2023 | L26: =MONTH(D26) -> 7 | M26: =DAY(D26) -> 15
A27: =A24+1 -> 8 | B27: =CONCATENATE(C27,"-",K27,"-0",L27,"-",M27) -> ABCB11-2023-08-15 | C27: =OFFSET(ir_3m!$C$4,calc_panel!A27,0) -> ABCB11 | D27: =D24 -> 45153 | E27: =IF(OFFSET(ebit_12m!$E$4,$A26,0)="","",OFFSET(ebit_12m!$E$4,$A26,0)) | F27: =IF(OFFSET(ir_3m!$E$4,$A26,0)="","",OFFSET(ir_3m!$E$4,$A26,0)) | G27: =IF(OFFSET(sharpe!$E$4,$A26,0)="","",OFFSET(sharpe!$E$4,$A26,0)) | H27: =IF(OFFSET(mkt_cap!$E$4,$A26,0)="","",OFFSET(mkt_cap!$E$4,$A26,0)) -> 4.1713621e+09 | I27: =IF(OFFSET(sector_c1!$D$4,$A27,0)="","",OFFSET(sector_c1!$D$4,$A27,0)) -> Bancos e Serviços Financeiros | K27: =YEAR(D27) -> 2023 | L27: =MONTH(D27) -> 8 | M27: =DAY(D27) -> 15
A28: =A25+1 -> 8 | B28: =CONCATENATE(C28,"-",K28,"-0",L28,"-",M28) -> ABCB11-2023-09-15 | C28: =OFFSET(ir_3m!$C$4,calc_panel!A28,0) -> ABCB11 | D28: =D25 -> 45184 | E28: =IF(OFFSET(ebit_12m!$F$4,$A26,0)="","",OFFSET(ebit_12m!$F$4,$A26,0)) | F28: =IF(OFFSET(ir_3m!$F$4,$A26,0)="","",OFFSET(ir_3m!$F$4,$A26,0)) | G28: =IF(OFFSET(sharpe!$F$4,$A26,0)="","",OFFSET(sharpe!$F$4,$A26,0)) | H28: =IF(OFFSET(mkt_cap!$F$4,$A26,0)="","",OFFSET(mkt_cap!$F$4,$A26,0)) -> 4689108392 | I28: =IF(OFFSET(sector_c1!$D$4,$A28,0)="","",OFFSET(sector_c1!$D$4,$A28,0)) -> Bancos e Serviços Financeiros | K28: =YEAR(D28) -> 2023 | L28: =MONTH(D28) -> 9 | M28: =DAY(D28) -> 15
A29: =A26+1 -> 9 | B29: =CONCATENATE(C29,"-",K29,"-0",L29,"-",M29) -> ABYA3-2023-07-15 | C29: =OFFSET(ir_3m!$C$4,calc_panel!A29,0) -> ABYA3 | D29: =D26 -> 45122 | E29: =IF(OFFSET(ebit_12m!$D$4,$A29,0)="","",OFFSET(ebit_12m!$D$4,$A29,0)) | F29: =IF(OFFSET(ir_3m!$D$4,$A29,0)="","",OFFSET(ir_3m!$D$4,$A29,0)) | G29: =IF(OFFSET(sharpe!$D$4,$A29,0)="","",OFFSET(sharpe!$D$4,$A29,0)) | H29: =IF(OFFSET(mkt_cap!$D$4,$A29,0)="","",OFFSET(mkt_cap!$D$4,$A29,0)) | I29: =IF(OFFSET(sector_c1!$D$4,$A29,0)="","",OFFSET(sector_c1!$D$4,$A29,0)) -> 0 | K29: =YEAR(D29) -> 2023 | L29: =MONTH(D29) -> 7 | M29: =DAY(D29) -> 15
A30: =A27+1 -> 9 | B30: =CONCATENATE(C30,"-",K30,"-0",L30,"-",M30) -> ABYA3-2023-08-15 | C30: =OFFSET(ir_3m!$C$4,calc_panel!A30,0) -> ABYA3 | D30: =D27 -> 45153 | E30: =IF(OFFSET(ebit_12m!$E$4,$A29,0)="","",OFFSET(ebit_12m!$E$4,$A29,0)) | F30: =IF(OFFSET(ir_3m!$E$4,$A29,0)="","",OFFSET(ir_3m!$E$4,$A29,0)) | G30: =IF(OFFSET(sharpe!$E$4,$A29,0)="","",OFFSET(sharpe!$E$4,$A29,0)) | H30: =IF(OFFSET(mkt_cap!$E$4,$A29,0)="","",OFFSET(mkt_cap!$E$4,$A29,0)) | I30: =IF(OFFSET(sector_c1!$D$4,$A30,0)="","",OFFSET(sector_c1!$D$4,$A30,0)) -> 0 | K30: =YEAR(D30) -> 2023 | L30: =MONTH(D30) -> 8 | M30: =DAY(D30) -> 15
A31: =A28+1 -> 9 | B31: =CONCATENATE(C31,"-",K31,"-0",L31,"-",M31) -> ABYA3-2023-09-15 | C31: =OFFSET(ir_3m!$C$4,calc_panel!A31,0) -> ABYA3 | D31: =D28 -> 45184 | E31: =IF(OFFSET(ebit_12m!$F$4,$A29,0)="","",OFFSET(ebit_12m!$F$4,$A29,0)) | F31: =IF(OFFSET(ir_3m!$F$4,$A29,0)="","",OFFSET(ir_3m!$F$4,$A29,0)) | G31: =IF(OFFSET(sharpe!$F$4,$A29,0)="","",OFFSET(sharpe!$F$4,$A29,0)) | H31: =IF(OFFSET(mkt_cap!$F$4,$A29,0)="","",OFFSET(mkt_cap!$F$4,$A29,0)) | I31: =IF(OFFSET(sector_c1!$D$4,$A31,0)="","",OFFSET(sector_c1!$D$4,$A31,0)) -> 0 | K31: =YEAR(D31) -> 2023 | L31: =MONTH(D31) -> 9 | M31: =DAY(D31) -> 15
A32: =A29+1 -> 10 | B32: =CONCATENATE(C32,"-",K32,"-0",L32,"-",M32) -> EALT3-2023-07-15 | C32: =OFFSET(ir_3m!$C$4,calc_panel!A32,0) -> EALT3 | D32: =D29 -> 45122 | E32: =IF(OFFSET(ebit_12m!$D$4,$A32,0)="","",OFFSET(ebit_12m!$D$4,$A32,0)) -> 53686000 | F32: =IF(OFFSET(ir_3m!$D$4,$A32,0)="","",OFFSET(ir_3m!$D$4,$A32,0)) | G32: =IF(OFFSET(sharpe!$D$4,$A32,0)="","",OFFSET(sharpe!$D$4,$A32,0)) | H32: =IF(OFFSET(mkt_cap!$D$4,$A32,0)="","",OFFSET(mkt_cap!$D$4,$A32,0)) -> 183817500 | I32: =IF(OFFSET(sector_c1!$D$4,$A32,0)="","",OFFSET(sector_c1!$D$4,$A32,0)) -> Indústria | K32: =YEAR(D32) -> 2023 | L32: =MONTH(D32) -> 7 | M32: =DAY(D32) -> 15
A33: =A30+1 -> 10 | B33: =CONCATENATE(C33,"-",K33,"-0",L33,"-",M33) -> EALT3-2023-08-15 | C33: =OFFSET(ir_3m!$C$4,calc_panel!A33,0) -> EALT3 | D33: =D30 -> 45153 | E33: =IF(OFFSET(ebit_12m!$E$4,$A32,0)="","",OFFSET(ebit_12m!$E$4,$A32,0)) -> 50303000 | F33: =IF(OFFSET(ir_3m!$E$4,$A32,0)="","",OFFSET(ir_3m!$E$4,$A32,0)) | G33: =IF(OFFSET(sharpe!$E$4,$A32,0)="","",OFFSET(sharpe!$E$4,$A32,0)) | H33: =IF(OFFSET(mkt_cap!$E$4,$A32,0)="","",OFFSET(mkt_cap!$E$4,$A32,0)) -> 180345000 | I33: =IF(OFFSET(sector_c1!$D$4,$A33,0)="","",OFFSET(sector_c1!$D$4,$A33,0)) -> Indústria | K33: =YEAR(D33) -> 2023 | L33: =MONTH(D33) -> 8 | M33: =DAY(D33) -> 15
A34: =A31+1 -> 10 | B34: =CONCATENATE(C34,"-",K34,"-0",L34,"-",M34) -> EALT3-2023-09-15 | C34: =OFFSET(ir_3m!$C$4,calc_panel!A34,0) -> EALT3 | D34: =D31 -> 45184 | E34: =IF(OFFSET(ebit_12m!$F$4,$A32,0)="","",OFFSET(ebit_12m!$F$4,$A32,0)) -> 50303000 | F34: =IF(OFFSET(ir_3m!$F$4,$A32,0)="","",OFFSET(ir_3m!$F$4,$A32,0)) | G34: =IF(OFFSET(sharpe!$F$4,$A32,0)="","",OFFSET(sharpe!$F$4,$A32,0)) | H34: =IF(OFFSET(mkt_cap!$F$4,$A32,0)="","",OFFSET(mkt_cap!$F$4,$A32,0)) -> 196417500 | I34: =IF(OFFSET(sector_c1!$D$4,$A34,0)="","",OFFSET(sector_c1!$D$4,$A34,0)) -> Indústria | K34: =YEAR(D34) -> 2023 | L34: =MONTH(D34) -> 9 | M34: =DAY(D34) -> 15
A35: =A32+1 -> 11 | B35: =CONCATENATE(C35,"-",K35,"-0",L35,"-",M35) -> EALT4-2023-07-15 | C35: =OFFSET(ir_3m!$C$4,calc_panel!A35,0) -> EALT4 | D35: =D32 -> 45122 | E35: =IF(OFFSET(ebit_12m!$D$4,$A35,0)="","",OFFSET(ebit_12m!$D$4,$A35,0)) -> 53686000 | F35: =IF(OFFSET(ir_3m!$D$4,$A35,0)="","",OFFSET(ir_3m!$D$4,$A35,0)) -> 0.70009563 | G35: =IF(OFFSET(sharpe!$D$4,$A35,0)="","",OFFSET(sharpe!$D$4,$A35,0)) -> 1.2421042 | H35: =IF(OFFSET(mkt_cap!$D$4,$A35,0)="","",OFFSET(mkt_cap!$D$4,$A35,0)) -> 183817500 | I35: =IF(OFFSET(sector_c1!$D$4,$A35,0)="","",OFFSET(sector_c1!$D$4,$A35,0)) -> Indústria | K35: =YEAR(D35) -> 2023 | L35: =MONTH(D35) -> 7 | M35: =DAY(D35) -> 15
A36: =A33+1 -> 11 | B36: =CONCATENATE(C36,"-",K36,"-0",L36,"-",M36) -> EALT4-2023-08-15 | C36: =OFFSET(ir_3m!$C$4,calc_panel!A36,0) -> EALT4 | D36: =D33 -> 45153 | E36: =IF(OFFSET(ebit_12m!$E$4,$A35,0)="","",OFFSET(ebit_12m!$E$4,$A35,0)) -> 50303000 | F36: =IF(OFFSET(ir_3m!$E$4,$A35,0)="","",OFFSET(ir_3m!$E$4,$A35,0)) -> 0.14604751 | G36: =IF(OFFSET(sharpe!$E$4,$A35,0)="","",OFFSET(sharpe!$E$4,$A35,0)) -> 1.1868813 | H36: =IF(OFFSET(mkt_cap!$E$4,$A35,0)="","",OFFSET(mkt_cap!$E$4,$A35,0)) -> 180345000 | I36: =IF(OFFSET(sector_c1!$D$4,$A36,0)="","",OFFSET(sector_c1!$D$4,$A36,0)) -> Indústria | K36: =YEAR(D36) -> 2023 | L36: =MONTH(D36) -> 8 | M36: =DAY(D36) -> 15
A37: =A34+1 -> 11 | B37: =CONCATENATE(C37,"-",K37,"-0",L37,"-",M37) -> EALT4-2023-09-15 | C37: =OFFSET(ir_3m!$C$4,calc_panel!A37,0) -> EALT4 | D37: =D34 -> 45184 | E37: =IF(OFFSET(ebit_12m!$F$4,$A35,0)="","",OFFSET(ebit_12m!$F$4,$A35,0)) -> 50303000 | F37: =IF(OFFSET(ir_3m!$F$4,$A35,0)="","",OFFSET(ir_3m!$F$4,$A35,0)) -> 0.70552401 | G37: =IF(OFFSET(sharpe!$F$4,$A35,0)="","",OFFSET(sharpe!$F$4,$A35,0)) -> 1.7240063 | H37: =IF(OFFSET(mkt_cap!$F$4,$A35,0)="","",OFFSET(mkt_cap!$F$4,$A35,0)) -> 196417500 | I37: =IF(OFFSET(sector_c1!$D$4,$A37,0)="","",OFFSET(sector_c1!$D$4,$A37,0)) -> Indústria | K37: =YEAR(D37) -> 2023 | L37: =MONTH(D37) -> 9 | M37: =DAY(D37) -> 15
A38: =A35+1 -> 12 | B38: =CONCATENATE(C38,"-",K38,"-0",L38,"-",M38) -> AVIL3-2023-07-15 | C38: =OFFSET(ir_3m!$C$4,calc_panel!A38,0) -> AVIL3 | D38: =D35 -> 45122 | E38: =IF(OFFSET(ebit_12m!$D$4,$A38,0)="","",OFFSET(ebit_12m!$D$4,$A38,0)) | F38: =IF(OFFSET(ir_3m!$D$4,$A38,0)="","",OFFSET(ir_3m!$D$4,$A38,0)) | G38: =IF(OFFSET(sharpe!$D$4,$A38,0)="","",OFFSET(sharpe!$D$4,$A38,0)) | H38: =IF(OFFSET(mkt_cap!$D$4,$A38,0)="","",OFFSET(mkt_cap!$D$4,$A38,0)) | I38: =IF(OFFSET(sector_c1!$D$4,$A38,0)="","",OFFSET(sector_c1!$D$4,$A38,0)) -> 0 | K38: =YEAR(D38) -> 2023 | L38: =MONTH(D38) -> 7 | M38: =DAY(D38) -> 15
A39: =A36+1 -> 12 | B39: =CONCATENATE(C39,"-",K39,"-0",L39,"-",M39) -> AVIL3-2023-08-15 | C39: =OFFSET(ir_3m!$C$4,calc_panel!A39,0) -> AVIL3 | D39: =D36 -> 45153 | E39: =IF(OFFSET(ebit_12m!$E$4,$A38,0)="","",OFFSET(ebit_12m!$E$4,$A38,0)) | F39: =IF(OFFSET(ir_3m!$E$4,$A38,0)="","",OFFSET(ir_3m!$E$4,$A38,0)) | G39: =IF(OFFSET(sharpe!$E$4,$A38,0)="","",OFFSET(sharpe!$E$4,$A38,0)) | H39: =IF(OFFSET(mkt_cap!$E$4,$A38,0)="","",OFFSET(mkt_cap!$E$4,$A38,0)) | I39: =IF(OFFSET(sector_c1!$D$4,$A39,0)="","",OFFSET(sector_c1!$D$4,$A39,0)) -> 0 | K39: =YEAR(D39) -> 2023 | L39: =MONTH(D39) -> 8 | M39: =DAY(D39) -> 15
A40: =A37+1 -> 12 | B40: =CONCATENATE(C40,"-",K40,"-0",L40,"-",M40) -> AVIL3-2023-09-15 | C40: =OFFSET(ir_3m!$C$4,calc_panel!A40,0) -> AVIL3 | D40: =D37 -> 45184 | E40: =IF(OFFSET(ebit_12m!$F$4,$A38,0)="","",OFFSET(ebit_12m!$F$4,$A38,0)) | F40: =IF(OFFSET(ir_3m!$F$4,$A38,0)="","",OFFSET(ir_3m!$F$4,$A38,0)) | G40: =IF(OFFSET(sharpe!$F$4,$A38,0)="","",OFFSET(sharpe!$F$4,$A38,0)) | H40: =IF(OFFSET(mkt_cap!$F$4,$A38,0)="","",OFFSET(mkt_cap!$F$4,$A38,0)) | I40: =IF(OFFSET(sector_c1!$D$4,$A40,0)="","",OFFSET(sector_c1!$D$4,$A40,0)) -> 0 | K40: =YEAR(D40) -> 2023 | L40: =MONTH(D40) -> 9 | M40: =DAY(D40) -> 15
...

Sheet panel
B1: id | C1: tickers | D1: dates | E1: ebit_12m | F1: ir_3m | G1: sharpe | H1: mkt_cap | I1: sector_c1
B2: ABCB11-2023-07-15 | C2: ABCB11 | D2: 45122 | H2: 4.013099e+09 | I2: Bancos e Serviços Financeiros
B3: ABCB11-2023-08-15 | C3: ABCB11 | D3: 45153 | H3: 4.1713621e+09 | I3: Bancos e Serviços Financeiros
B4: ABCB11-2023-09-15 | C4: ABCB11 | D4: 45184 | H4: 4689108392 | I4: Bancos e Serviços Financeiros
B5: ABCB3-2023-07-15 | C5: ABCB3 | D5: 45122 | H5: 4.013099e+09 | I5: Bancos e Serviços Financeiros
B6: ABCB3-2023-08-15 | C6: ABCB3 | D6: 45153 | H6: 4.1713621e+09 | I6: Bancos e Serviços Financeiros
B7: ABCB3-2023-09-15 | C7: ABCB3 | D7: 45184 | H7: 4689108392 | I7: Bancos e Serviços Financeiros
B8: ABCB4-2023-07-15 | C8: ABCB4 | D8: 45122 | F8: 0.36039598 | G8: -0.46539838 | H8: 4.013099e+09 | I8: Bancos e Serviços Financeiros
B9: ABCB4-2023-08-15 | C9: ABCB4 | D9: 45153 | F9: 2.4845142 | G9: -0.027505853 | H9: 4.1713621e+09 | I9: Bancos e Serviços Financeiros
B10: ABCB4-2023-09-15 | C10: ABCB4 | D10: 45184 | F10: 5.7737358 | G10: 1.7853309 | H10: 4689108392 | I10: Bancos e Serviços Financeiros
B11: ABYA3-2023-07-15 | C11: ABYA3 | D11: 45122
B12: ABYA3-2023-08-15 | C12: ABYA3 | D12: 45153
B13: ABYA3-2023-09-15 | C13: ABYA3 | D13: 45184
B14: ADHM3-2023-07-15 | C14: ADHM3 | D14: 45122 | I14: Consumo Não-Cíclico
B15: ADHM3-2023-08-15 | C15: ADHM3 | D15: 45153 | I15: Consumo Não-Cíclico
B16: ADHM3-2023-09-15 | C16: ADHM3 | D16: 45184 | I16: Consumo Não-Cíclico
B17: AERI3-2023-07-15 | C17: AERI3 | D17: 45122 | E17: 254680000 | F17: -0.77059577 | G17: -0.071191061 | H17: 9.1230552e+08 | I17: Indústria
B18: AERI3-2023-08-15 | C18: AERI3 | D18: 45153 | E18: 277859000 | F18: -1.9343979 | G18: -0.10539752 | H18: 8.5996012e+08 | I18: Indústria
B19: AERI3-2023-09-15 | C19: AERI3 | D19: 45184 | E19: 277859000 | F19: -1.742498 | G19: -0.75354202 | H19: 6.9544601e+08 | I19: Indústria
B20: AESB3-2023-07-15 | C20: AESB3 | D20: 45122 | E20: 767946000 | F20: 0.7310006 | G20: 2.0047721 | H20: 7.1027423e+09 | I20: Utilidade Pública
B21: AESB3-2023-08-15 | C21: AESB3 | D21: 45153 | E21: 848568000 | F21: -3.4132854 | G21: 0.16494726 | H21: 6.4767379e+09 | I21: Utilidade Pública
B22: AESB3-2023-09-15 | C22: AESB3 | D22: 45184 | E22: 848568000 | F22: -1.0414439 | G22: 0.78926 | H22: 6.9883761e+09 | I22: Utilidade Pública
B23: APPA3-2023-07-15 | C23: APPA3 | D23: 45122
B24: APPA3-2023-08-15 | C24: APPA3 | D24: 45153
B25: APPA3-2023-09-15 | C25: APPA3 | D25: 45184
B26: APPA4-2023-07-15 | C26: APPA4 | D26: 45122
B27: APPA4-2023-08-15 | C27: APPA4 | D27: 45153
B28: APPA4-2023-09-15 | C28: APPA4 | D28: 45184
B29: AVIL3-2023-07-15 | C29: AVIL3 | D29: 45122
B30: AVIL3-2023-08-15 | C30: AVIL3 | D30: 45153
B31: AVIL3-2023-09-15 | C31: AVIL3 | D31: 45184
B32: AVIL4-2023-07-15 | C32: AVIL4 | D32: 45122
B33: AVIL4-2023-08-15 | C33: AVIL4 | D33: 45153
B34: AVIL4-2023-09-15 | C34: AVIL4 | D34: 45184
B35: EALT3-2023-07-15 | C35: EALT3 | D35: 45122 | E35: 53686000 | H35: 183817500 | I35: Indústria
B36: EALT3-2023-08-15 | C36: EALT3 | D36: 45153 | E36: 50303000 | H36: 180345000 | I36: Indústria
B37: EALT3-2023-09-15 | C37: EALT3 | D37: 45184 | E37: 50303000 | H37: 196417500 | I37: Indústria
B38: EALT4-2023-07-15 | C38: EALT4 | D38: 45122 | E38: 53686000 | F38: 0.70009563 | G38: 1.2421042 | H38: 183817500 | I38: Indústria
B39: EALT4-2023-08-15 | C39: EALT4 | D39: 45153 | E39: 50303000 | F39: 0.14604751 | G39: 1.1868813 | H39: 180345000 | I39: Indústria
B40: EALT4-2023-09-15 | C40: EALT4 | D40: 45184 | E40: 50303000 | F40: 0.70552401 | G40: 1.7240063 | H40: 196417500 | I40: Indústria
...

Sheet calc_wins_panel
B1: id | C1: tickers | D1: dates | E1: ebit_12m | F1: ir_3m | G1: sharpe | H1: mkt_cap | I1: sector_c1
B2: ABCB11-2023-07-15 | C2: ABCB11 | D2: 45122 | H2: 4.013099e+09 | I2: Bancos e Serviços Financeiros
B3: ABCB11-2023-08-15 | C3: ABCB11 | D3: 45153 | H3: 4.1713621e+09 | I3: Bancos e Serviços Financeiros
B4: ABCB11-2023-09-15 | C4: ABCB11 | D4: 45184 | H4: 4689108392 | I4: Bancos e Serviços Financeiros
A5: 1 | B5: ABCB3-2023-07-15 | C5: ABCB3 | D5: 45122 | H5: 4.013099e+09 | I5: Bancos e Serviços Financeiros
A6: 1 | B6: ABCB3-2023-08-15 | C6: ABCB3 | D6: 45153 | H6: 4.1713621e+09 | I6: Bancos e Serviços Financeiros
A7: 1 | B7: ABCB3-2023-09-15 | C7: ABCB3 | D7: 45184 | H7: 4689108392 | I7: Bancos e Serviços Financeiros
A8: =A5+1 -> 2 | B8: ABCB4-2023-07-15 | C8: ABCB4 | D8: 45122 | F8: 0.36039598 | G8: -0.46539838 | H8: 4.013099e+09 | I8: Bancos e Serviços Financeiros
A9: =A6+1 -> 2 | B9: ABCB4-2023-08-15 | C9: ABCB4 | D9: 45153 | F9: 2.4845142 | G9: -0.027505853 | H9: 4.1713621e+09 | I9: Bancos e Serviços Financeiros
A10: =A7+1 -> 2 | B10: ABCB4-2023-09-15 | C10: ABCB4 | D10: 45184 | F10: 5.7737358 | G10: 1.7853309 | H10: 4689108392 | I10: Bancos e Serviços Financeiros
A11: =A8+1 -> 3 | B11: ABYA3-2023-07-15 | C11: ABYA3 | D11: 45122
A12: =A9+1 -> 3 | B12: ABYA3-2023-08-15 | C12: ABYA3 | D12: 45153
A13: =A10+1 -> 3 | B13: ABYA3-2023-09-15 | C13: ABYA3 | D13: 45184
A14: =A11+1 -> 4 | B14: ADHM3-2023-07-15 | C14: ADHM3 | D14: 45122 | I14: Consumo Não-Cíclico
A15: =A12+1 -> 4 | B15: ADHM3-2023-08-15 | C15: ADHM3 | D15: 45153 | I15: Consumo Não-Cíclico
A16: =A13+1 -> 4 | B16: ADHM3-2023-09-15 | C16: ADHM3 | D16: 45184 | I16: Consumo Não-Cíclico
A17: =A14+1 -> 5 | B17: AERI3-2023-07-15 | C17: AERI3 | D17: 45122 | E17: 254680000 | F17: -0.77059577 | G17: -0.071191061 | H17: 9.1230552e+08 | I17: Indústria
A18: =A15+1 -> 5 | B18: AERI3-2023-08-15 | C18: AERI3 | D18: 45153 | E18: 277859000 | F18: -1.9343979 | G18: -0.10539752 | H18: 8.5996012e+08 | I18: Indústria
A19: =A16+1 -> 5 | B19: AERI3-2023-09-15 | C19: AERI3 | D19: 45184 | E19: 277859000 | F19: -1.742498 | G19: -0.75354202 | H19: 6.9544601e+08 | I19: Indústria
A20: =A17+1 -> 6 | B20: AESB3-2023-07-15 | C20: AESB3 | D20: 45122 | E20: 767946000 | F20: 0.7310006 | G20: 2.0047721 | H20: 7.1027423e+09 | I20: Utilidade Pública
A21: =A18+1 -> 6 | B21: AESB3-2023-08-15 | C21: AESB3 | D21: 45153 | E21: 848568000 | F21: -3.4132854 | G21: 0.16494726 | H21: 6.4767379e+09 | I21: Utilidade Pública
A22: =A19+1 -> 6 | B22: AESB3-2023-09-15 | C22: AESB3 | D22: 45184 | E22: 848568000 | F22: -1.0414439 | G22: 0.78926 | H22: 6.9883761e+09 | I22: Utilidade Pública
A23: =A20+1 -> 7 | B23: APPA3-2023-07-15 | C23: APPA3 | D23: 45122
A24: =A21+1 -> 7 | B24: APPA3-2023-08-15 | C24: APPA3 | D24: 45153
A25: =A22+1 -> 7 | B25: APPA3-2023-09-15 | C25: APPA3 | D25: 45184
A26: =A23+1 -> 8 | B26: APPA4-2023-07-15 | C26: APPA4 | D26: 45122
A27: =A24+1 -> 8 | B27: APPA4-2023-08-15 | C27: APPA4 | D27: 45153
A28: =A25+1 -> 8 | B28: APPA4-2023-09-15 | C28: APPA4 | D28: 45184
A29: =A26+1 -> 9 | B29: AVIL3-2023-07-15 | C29: AVIL3 | D29: 45122
A30: =A27+1 -> 9 | B30: AVIL3-2023-08-15 | C30: AVIL3 | D30: 45153
A31: =A28+1 -> 9 | B31: AVIL3-2023-09-15 | C31: AVIL3 | D31: 45184
A32: =A29+1 -> 10 | B32: AVIL4-2023-07-15 | C32: AVIL4 | D32: 45122
A33: =A30+1 -> 10 | B33: AVIL4-2023-08-15 | C33: AVIL4 | D33: 45153
A34: =A31+1 -> 10 | B34: AVIL4-2023-09-15 | C34: AVIL4 | D34: 45184
A35: =A32+1 -> 11 | B35: EALT3-2023-07-15 | C35: EALT3 | D35: 45122 | E35: 53686000 | H35: 183817500 | I35: Indústria
A36: =A33+1 -> 11 | B36: EALT3-2023-08-15 | C36: EALT3 | D36: 45153 | E36: 50303000 | H36: 180345000 | I36: Indústria
A37: =A34+1 -> 11 | B37: EALT3-2023-09-15 | C37: EALT3 | D37: 45184 | E37: 50303000 | H37: 196417500 | I37: Indústria
A38: =A35+1 -> 12 | B38: EALT4-2023-07-15 | C38: EALT4 | D38: 45122 | E38: 53686000 | F38: 0.70009563 | G38: 1.2421042 | H38: 183817500 | I38: Indústria
A39: =A36+1 -> 12 | B39: EALT4-2023-08-15 | C39: EALT4 | D39: 45153 | E39: 50303000 | F39: 0.14604751 | G39: 1.1868813 | H39: 180345000 | I39: Indústria
A40: =A37+1 -> 12 | B40: EALT4-2023-09-15 | C40: EALT4 | D40: 45184 | E40: 50303000 | F40: 0.70552401 | G40: 1.7240063 | H40: 196417500 | I40: Indústria
...

Sheet winsorized_panel
B1: id | C1: tickers | D1: dates | E1: ebit_12m | F1: ir_3m | G1: sharpe | H1: mkt_cap | I1: sector_c1
B2: ABCB11-2023-07-15 | C2: ABCB11 | D2: 45122 | H2: 4.013099e+09 | I2: Bancos e Serviços Financeiros
B3: ABCB11-2023-08-15 | C3: ABCB11 | D3: 45153 | H3: 4.1713621e+09 | I3: Bancos e Serviços Financeiros
B4: ABCB11-2023-09-15 | C4: ABCB11 | D4: 45184 | H4: 4689108392 | I4: Bancos e Serviços Financeiros
B5: ABCB3-2023-07-15 | C5: ABCB3 | D5: 45122 | H5: 4.013099e+09 | I5: Bancos e Serviços Financeiros
B6: ABCB3-2023-08-15 | C6: ABCB3 | D6: 45153 | H6: 4.1713621e+09 | I6: Bancos e Serviços Financeiros
B7: ABCB3-2023-09-15 | C7: ABCB3 | D7: 45184 | H7: 4689108392 | I7: Bancos e Serviços Financeiros
B8: ABCB4-2023-07-15 | C8: ABCB4 | D8: 45122 | F8: 0.36039598 | G8: -0.46539838 | H8: 4.013099e+09 | I8: Bancos e Serviços Financeiros
B9: ABCB4-2023-08-15 | C9: ABCB4 | D9: 45153 | F9: 2.2717768 | G9: -0.027505853 | H9: 4.1713621e+09 | I9: Bancos e Serviços Financeiros
B10: ABCB4-2023-09-15 | C10: ABCB4 | D10: 45184 | F10: 5.3415748 | G10: 1.7776653 | H10: 4689108392 | I10: Bancos e Serviços Financeiros
B11: ABYA3-2023-07-15 | C11: ABYA3 | D11: 45122
B12: ABYA3-2023-08-15 | C12: ABYA3 | D12: 45153
B13: ABYA3-2023-09-15 | C13: ABYA3 | D13: 45184
B14: ADHM3-2023-07-15 | C14: ADHM3 | D14: 45122 | I14: Consumo Não-Cíclico
B15: ADHM3-2023-08-15 | C15: ADHM3 | D15: 45153 | I15: Consumo Não-Cíclico
B16: ADHM3-2023-09-15 | C16: ADHM3 | D16: 45184 | I16: Consumo Não-Cíclico
B17: AERI3-2023-07-15 | C17: AERI3 | D17: 45122 | E17: 254680000 | F17: -0.72805761 | G17: -0.071191061 | H17: 9.1230552e+08 | I17: Indústria
B18: AERI3-2023-08-15 | C18: AERI3 | D18: 45153 | E18: 277859000 | F18: -1.9343979 | G18: -0.10539752 | H18: 8.5996012e+08 | I18: Indústria
B19: AERI3-2023-09-15 | C19: AERI3 | D19: 45184 | E19: 277859000 | F19: -1.6548662 | G19: -0.60255634 | H19: 6.9544601e+08 | I19: Indústria
B20: AESB3-2023-07-15 | C20: AESB3 | D20: 45122 | E20: 767946000 | F20: 0.72713748 | G20: 2.0047721 | H20: 7.1027423e+09 | I20: Utilidade Pública
B21: AESB3-2023-08-15 | C21: AESB3 | D21: 45153 | E21: 848568000 | F21: -3.2284245 | G21: 0.16494726 | H21: 6.4767379e+09 | I21: Utilidade Pública
B22: AESB3-2023-09-15 | C22: AESB3 | D22: 45184 | E22: 848568000 | F22: -1.0414439 | G22: 0.78926 | H22: 6.9883761e+09 | I22: Utilidade Pública
B23: APPA3-2023-07-15 | C23: APPA3 | D23: 45122
B24: APPA3-2023-08-15 | C24: APPA3 | D24: 45153
B25: APPA3-2023-09-15 | C25: APPA3 | D25: 45184
B26: APPA4-2023-07-15 | C26: APPA4 | D26: 45122
B27: APPA4-2023-08-15 | C27: APPA4 | D27: 45153
B28: APPA4-2023-09-15 | C28: APPA4 | D28: 45184
B29: AVIL3-2023-07-15 | C29: AVIL3 | D29: 45122
B30: AVIL3-2023-08-15 | C30: AVIL3 | D30: 45153
B31: AVIL3-2023-09-15 | C31: AVIL3 | D31: 45184
B32: AVIL4-2023-07-15 | C32: AVIL4 | D32: 45122
B33: AVIL4-2023-08-15 | C33: AVIL4 | D33: 45153
B34: AVIL4-2023-09-15 | C34: AVIL4 | D34: 45184
B35: EALT3-2023-07-15 | C35: EALT3 | D35: 45122 | E35: 53686000 | H35: 183817500 | I35: Indústria
B36: EALT3-2023-08-15 | C36: EALT3 | D36: 45153 | E36: 50303000 | H36: 180345000 | I36: Indústria
B37: EALT3-2023-09-15 | C37: EALT3 | D37: 45184 | E37: 50303000 | H37: 196417500 | I37: Indústria
B38: EALT4-2023-07-15 | C38: EALT4 | D38: 45122 | E38: 53686000 | F38: 0.70009563 | G38: 1.2421042 | H38: 183817500 | I38: Indústria
B39: EALT4-2023-08-15 | C39: EALT4 | D39: 45153 | E39: 50303000 | F39: 0.14604751 | G39: 1.0591396 | H39: 180345000 | I39: Indústria
B40: EALT4-2023-09-15 | C40: EALT4 | D40: 45184 | E40: 50303000 | F40: 0.70552401 | G40: 1.7240063 | H40: 196417500 | I40: Indústria
...

Sheet calc_norm_panel
B1: id | C1: tickers | D1: dates | E1: ebit_12m | F1: ir_3m | G1: sharpe | H1: mkt_cap
B2: ABCB11-2023-07-15 | C2: ABCB11 | D2: 45122 | H2: 4.013099e+09
B3: ABCB11-2023-08-15 | C3: ABCB11 | D3: 45153 | H3: 4.1713621e+09
B4: ABCB11-2023-09-15 | C4: ABCB11 | D4: 45184 | H4: 4689108392
B5: ABCB3-2023-07-15 | C5: ABCB3 | D5: 45122 | H5: 4.013099e+09
B6: ABCB3-2023-08-15 | C6: ABCB3 | D6: 45153 | H6: 4.1713621e+09
B7: ABCB3-2023-09-15 | C7: ABCB3 | D7: 45184 | H7: 4689108392
B8: ABCB4-2023-07-15 | C8: ABCB4 | D8: 45122 | F8: 0.36039598 | G8: -0.46539838 | H8: 4.013099e+09
B9: ABCB4-2023-08-15 | C9: ABCB4 | D9: 45153 | F9: 2.2717768 | G9: -0.027505853 | H9: 4.1713621e+09
B10: ABCB4-2023-09-15 | C10: ABCB4 | D10: 45184 | F10: 5.3415748 | G10: 1.7776653 | H10: 4689108392
B11: ABYA3-2023-07-15 | C11: ABYA3 | D11: 45122
B12: ABYA3-2023-08-15 | C12: ABYA3 | D12: 45153
B13: ABYA3-2023-09-15 | C13: ABYA3 | D13: 45184
B14: ADHM3-2023-07-15 | C14: ADHM3 | D14: 45122
B15: ADHM3-2023-08-15 | C15: ADHM3 | D15: 45153
B16: ADHM3-2023-09-15 | C16: ADHM3 | D16: 45184
B17: AERI3-2023-07-15 | C17: AERI3 | D17: 45122 | E17: 254680000 | F17: -0.72805761 | G17: -0.071191061 | H17: 9.1230552e+08
B18: AERI3-2023-08-15 | C18: AERI3 | D18: 45153 | E18: 277859000 | F18: -1.9343979 | G18: -0.10539752 | H18: 8.5996012e+08
B19: AERI3-2023-09-15 | C19: AERI3 | D19: 45184 | E19: 277859000 | F19: -1.6548662 | G19: -0.60255634 | H19: 6.9544601e+08
B20: AESB3-2023-07-15 | C20: AESB3 | D20: 45122 | E20: 767946000 | F20: 0.72713748 | G20: 2.0047721 | H20: 7.1027423e+09
B21: AESB3-2023-08-15 | C21: AESB3 | D21: 45153 | E21: 848568000 | F21: -3.2284245 | G21: 0.16494726 | H21: 6.4767379e+09
B22: AESB3-2023-09-15 | C22: AESB3 | D22: 45184 | E22: 848568000 | F22: -1.0414439 | G22: 0.78926 | H22: 6.9883761e+09
B23: APPA3-2023-07-15 | C23: APPA3 | D23: 45122
B24: APPA3-2023-08-15 | C24: APPA3 | D24: 45153
B25: APPA3-2023-09-15 | C25: APPA3 | D25: 45184
B26: APPA4-2023-07-15 | C26: APPA4 | D26: 45122
B27: APPA4-2023-08-15 | C27: APPA4 | D27: 45153
B28: APPA4-2023-09-15 | C28: APPA4 | D28: 45184
B29: AVIL3-2023-07-15 | C29: AVIL3 | D29: 45122
B30: AVIL3-2023-08-15 | C30: AVIL3 | D30: 45153
B31: AVIL3-2023-09-15 | C31: AVIL3 | D31: 45184
B32: AVIL4-2023-07-15 | C32: AVIL4 | D32: 45122
B33: AVIL4-2023-08-15 | C33: AVIL4 | D33: 45153
B34: AVIL4-2023-09-15 | C34: AVIL4 | D34: 45184
B35: EALT3-2023-07-15 | C35: EALT3 | D35: 45122 | E35: 53686000 | H35: 183817500
B36: EALT3-2023-08-15 | C36: EALT3 | D36: 45153 | E36: 50303000 | H36: 180345000
B37: EALT3-2023-09-15 | C37: EALT3 | D37: 45184 | E37: 50303000 | H37: 196417500
B38: EALT4-2023-07-15 | C38: EALT4 | D38: 45122 | E38: 53686000 | F38: 0.70009563 | G38: 1.2421042 | H38: 183817500
B39: EALT4-2023-08-15 | C39: EALT4 | D39: 45153 | E39: 50303000 | F39: 0.14604751 | G39: 1.0591396 | H39: 180345000
B40: EALT4-2023-09-15 | C40: EALT4 | D40: 45184 | E40: 50303000 | F40: 0.70552401 | G40: 1.7240063 | H40: 196417500
...

Sheet normalized_panel
B1: id | C1: tickers | D1: dates | E1: ebit_12m | F1: ir_3m | G1: sharpe | H1: mkt_cap | I1: sector_c1
B2: ABCB11-2023-07-15 | C2: ABCB11 | D2: 45122 | H2: 0.028966442 | I2: Bancos e Serviços Financeiros
B3: ABCB11-2023-08-15 | C3: ABCB11 | D3: 45153 | H3: 0.096020562 | I3: Bancos e Serviços Financeiros
B4: ABCB11-2023-09-15 | C4: ABCB11 | D4: 45184 | H4: 0.19436808 | I4: Bancos e Serviços Financeiros
B5: ABCB3-2023-07-15 | C5: ABCB3 | D5: 45122 | H5: 0.028966442 | I5: Bancos e Serviços Financeiros
B6: ABCB3-2023-08-15 | C6: ABCB3 | D6: 45153 | H6: 0.096020562 | I6: Bancos e Serviços Financeiros
B7: ABCB3-2023-09-15 | C7: ABCB3 | D7: 45184 | H7: 0.19436808 | I7: Bancos e Serviços Financeiros
B8: ABCB4-2023-07-15 | C8: ABCB4 | D8: 45122 | F8: 0.49595556 | G8: -0.85425883 | H8: 0.028966442 | I8: Bancos e Serviços Financeiros
B9: ABCB4-2023-08-15 | C9: ABCB4 | D9: 45153 | F9: 1 | G9: -0.36537734 | H9: 0.096020562 | I9: Bancos e Serviços Financeiros
B10: ABCB4-2023-09-15 | C10: ABCB4 | D10: 45184 | F10: 1 | G10: 1 | H10: 0.19436808 | I10: Bancos e Serviços Financeiros
B11: ABYA3-2023-07-15 | C11: ABYA3 | D11: 45122
B12: ABYA3-2023-08-15 | C12: ABYA3 | D12: 45153
B13: ABYA3-2023-09-15 | C13: ABYA3 | D13: 45184
B14: ADHM3-2023-07-15 | C14: ADHM3 | D14: 45122 | I14: Consumo Não-Cíclico
B15: ADHM3-2023-08-15 | C15: ADHM3 | D15: 45153 | I15: Consumo Não-Cíclico
B16: ADHM3-2023-09-15 | C16: ADHM3 | D16: 45184 | I16: Consumo Não-Cíclico
B17: AERI3-2023-07-15 | C17: AERI3 | D17: 45122 | E17: -0.35548701 | F17: -1 | G17: -0.59353536 | H17: -0.80424795 | I17: Indústria
B18: AERI3-2023-08-15 | C18: AERI3 | D18: 45153 | E18: -0.36107576 | F18: -0.52946209 | G18: -0.46324876 | H18: -0.81336283 | I18: Indústria
B19: AERI3-2023-09-15 | C19: AERI3 | D19: 45184 | E19: -0.36107576 | F19: -1 | G19: -1 | H19: -0.8673348 | I19: Indústria
B20: AESB3-2023-07-15 | C20: AESB3 | D20: 45122 | E20: 1 | F20: 1 | G20: 0.77947905 | H20: 0.85918464 | I20: Utilidade Pública
B21: AESB3-2023-08-15 | C21: AESB3 | D21: 45153 | E21: 1 | F21: -1 | G21: -0.1235587 | H21: 0.72912716 | I21: Utilidade Pública
B22: AESB3-2023-09-15 | C22: AESB3 | D22: 45184 | E22: 1 | F22: -0.82464732 | G22: 0.16948464 | H22: 0.80562133 | I22: Utilidade Pública
B23: APPA3-2023-07-15 | C23: APPA3 | D23: 45122
B24: APPA3-2023-08-15 | C24: APPA3 | D24: 45153
B25: APPA3-2023-09-15 | C25: APPA3 | D25: 45184
B26: APPA4-2023-07-15 | C26: APPA4 | D26: 45122
B27: APPA4-2023-08-15 | C27: APPA4 | D27: 45153
B28: APPA4-2023-09-15 | C28: APPA4 | D28: 45184
B29: AVIL3-2023-07-15 | C29: AVIL3 | D29: 45122
B30: AVIL3-2023-08-15 | C30: AVIL3 | D30: 45153
B31: AVIL3-2023-09-15 | C31: AVIL3 | D31: 45184
B32: AVIL4-2023-07-15 | C32: AVIL4 | D32: 45122
B33: AVIL4-2023-08-15 | C33: AVIL4 | D33: 45153
B34: AVIL4-2023-09-15 | C34: AVIL4 | D34: 45184
B35: EALT3-2023-07-15 | C35: EALT3 | D35: 45122 | E35: -0.88629317 | H35: -1 | I35: Indústria
B36: EALT3-2023-08-15 | C36: EALT3 | D36: 45153 | E36: -0.90377081 | H36: -1 | I36: Indústria
B37: EALT3-2023-09-15 | C37: EALT3 | D37: 45184 | E37: -0.90377081 | H37: -1 | I37: Indústria
B38: EALT4-2023-07-15 | C38: EALT4 | D38: 45122 | E38: -0.88629317 | F38: 0.96283406 | G38: 0.27506063 | H38: -1 | I38: Indústria
B39: EALT4-2023-08-15 | C39: EALT4 | D39: 45153 | E39: -0.90377081 | F39: 0.22703582 | G39: 1 | H39: -1 | I39: Indústria
B40: EALT4-2023-09-15 | C40: EALT4 | D40: 45184 | E40: -0.90377081 | F40: -0.32525974 | G40: 0.95491258 | H40: -1 | I40: Indústria
...

Sheet normalized_panel_banks_filled
B1: id | C1: tickers | D1: dates | E1: ebit_12m | F1: ir_3m | G1: sharpe | H1: mkt_cap | I1: sector_c1
B2: ABCB11-2023-07-15 | C2: ABCB11 | D2: 45122 | H2: 0.028966442 | I2: Bancos e Serviços Financeiros
B3: ABCB11-2023-08-15 | C3: ABCB11 | D3: 45153 | H3: 0.096020562 | I3: Bancos e Serviços Financeiros
B4: ABCB11-2023-09-15 | C4: ABCB11 | D4: 45184 | H4: 0.19436808 | I4: Bancos e Serviços Financeiros
B5: ABCB3-2023-07-15 | C5: ABCB3 | D5: 45122 | H5: 0.028966442 | I5: Bancos e Serviços Financeiros
B6: ABCB3-2023-08-15 | C6: ABCB3 | D6: 45153 | H6: 0.096020562 | I6: Bancos e Serviços Financeiros
B7: ABCB3-2023-09-15 | C7: ABCB3 | D7: 45184 | H7: 0.19436808 | I7: Bancos e Serviços Financeiros
B8: ABCB4-2023-07-15 | C8: ABCB4 | D8: 45122 | E8: =AVERAGE(F8:G8) -> -0.17915164 | F8: 0.49595556 | G8: -0.85425883 | H8: 0.028966442 | I8: Bancos e Serviços Financeiros
B9: ABCB4-2023-08-15 | C9: ABCB4 | D9: 45153 | E9: =AVERAGE(F9:G9) -> 0.31731133 | F9: 1 | G9: -0.36537734 | H9: 0.096020562 | I9: Bancos e Serviços Financeiros
B10: ABCB4-2023-09-15 | C10: ABCB4 | D10: 45184 | E10: =AVERAGE(F10:G10) -> 1 | F10: 1 | G10: 1 | H10: 0.19436808 | I10: Bancos e Serviços Financeiros
B11: ABYA3-2023-07-15 | C11: ABYA3 | D11: 45122
B12: ABYA3-2023-08-15 | C12: ABYA3 | D12: 45153
B13: ABYA3-2023-09-15 | C13: ABYA3 | D13: 45184
B14: ADHM3-2023-07-15 | C14: ADHM3 | D14: 45122 | I14: Consumo Não-Cíclico
B15: ADHM3-2023-08-15 | C15: ADHM3 | D15: 45153 | I15: Consumo Não-Cíclico
B16: ADHM3-2023-09-15 | C16: ADHM3 | D16: 45184 | I16: Consumo Não-Cíclico
B17: AERI3-2023-07-15 | C17: AERI3 | D17: 45122 | E17: -0.35548701 | F17: -1 | G17: -0.59353536 | H17: -0.80424795 | I17: Indústria
B18: AERI3-2023-08-15 | C18: AERI3 | D18: 45153 | E18: -0.36107576 | F18: -0.52946209 | G18: -0.46324876 | H18: -0.81336283 | I18: Indústria
B19: AERI3-2023-09-15 | C19: AERI3 | D19: 45184 | E19: -0.36107576 | F19: -1 | G19: -1 | H19: -0.8673348 | I19: Indústria
B20: AESB3-2023-07-15 | C20: AESB3 | D20: 45122 | E20: 1 | F20: 1 | G20: 0.77947905 | H20: 0.85918464 | I20: Utilidade Pública
B21: AESB3-2023-08-15 | C21: AESB3 | D21: 45153 | E21: 1 | F21: -1 | G21: -0.1235587 | H21: 0.72912716 | I21: Utilidade Pública
B22: AESB3-2023-09-15 | C22: AESB3 | D22: 45184 | E22: 1 | F22: -0.82464732 | G22: 0.16948464 | H22: 0.80562133 | I22: Utilidade Pública
B23: APPA3-2023-07-15 | C23: APPA3 | D23: 45122
B24: APPA3-2023-08-15 | C24: APPA3 | D24: 45153
B25: APPA3-2023-09-15 | C25: APPA3 | D25: 45184
B26: APPA4-2023-07-15 | C26: APPA4 | D26: 45122
B27: APPA4-2023-08-15 | C27: APPA4 | D27: 45153
B28: APPA4-2023-09-15 | C28: APPA4 | D28: 45184
B29: AVIL3-2023-07-15 | C29: AVIL3 | D29: 45122
B30: AVIL3-2023-08-15 | C30: AVIL3 | D30: 45153
B31: AVIL3-2023-09-15 | C31: AVIL3 | D31: 45184
B32: AVIL4-2023-07-15 | C32: AVIL4 | D32: 45122
B33: AVIL4-2023-08-15 | C33: AVIL4 | D33: 45153
B34: AVIL4-2023-09-15 | C34: AVIL4 | D34: 45184
B35: EALT3-2023-07-15 | C35: EALT3 | D35: 45122 | E35: -0.88629317 | H35: -1 | I35: Indústria
B36: EALT3-2023-08-15 | C36: EALT3 | D36: 45153 | E36: -0.90377081 | H36: -1 | I36: Indústria
B37: EALT3-2023-09-15 | C37: EALT3 | D37: 45184 | E37: -0.90377081 | H37: -1 | I37: Indústria
B38: EALT4-2023-07-15 | C38: EALT4 | D38: 45122 | E38: -0.88629317 | F38: 0.96283406 | G38: 0.27506063 | H38: -1 | I38: Indústria
B39: EALT4-2023-08-15 | C39: EALT4 | D39: 45153 | E39: -0.90377081 | F39: 0.22703582 | G39: 1 | H39: -1 | I39: Indústria
B40: EALT4-2023-09-15 | C40: EALT4 | D40: 45184 | E40: -0.90377081 | F40: -0.32525974 | G40: 0.95491258 | H40: -1 | I40: Indústria
...

Sheet calc_sector_filled_panel
B1: id | C1: tickers | D1: dates | E1: ebit_12m | F1: ir_3m | G1: sharpe | H1: mkt_cap | I1: sector_c1
B2: ABCB11-2023-07-15 | C2: ABCB11 | D2: 45122 | H2: 0.028966442 | I2: Bancos e Serviços Financeiros
B3: ABCB11-2023-08-15 | C3: ABCB11 | D3: 45153 | H3: 0.096020562 | I3: Bancos e Serviços Financeiros
B4: ABCB11-2023-09-15 | C4: ABCB11 | D4: 45184 | H4: 0.19436808 | I4: Bancos e Serviços Financeiros
B5: ABCB3-2023-07-15 | C5: ABCB3 | D5: 45122 | H5: 0.028966442 | I5: Bancos e Serviços Financeiros
B6: ABCB3-2023-08-15 | C6: ABCB3 | D6: 45153 | H6: 0.096020562 | I6: Bancos e Serviços Financeiros
B7: ABCB3-2023-09-15 | C7: ABCB3 | D7: 45184 | H7: 0.19436808 | I7: Bancos e Serviços Financeiros
B8: ABCB4-2023-07-15 | C8: ABCB4 | D8: 45122 | E8: -0.17915164 | F8: 0.49595556 | G8: -0.85425883 | H8: 0.028966442 | I8: Bancos e Serviços Financeiros
B9: ABCB4-2023-08-15 | C9: ABCB4 | D9: 45153 | E9: 0.31731133 | F9: 1 | G9: -0.36537734 | H9: 0.096020562 | I9: Bancos e Serviços Financeiros
B10: ABCB4-2023-09-15 | C10: ABCB4 | D10: 45184 | E10: 1 | F10: 1 | G10: 1 | H10: 0.19436808 | I10: Bancos e Serviços Financeiros
B11: ABYA3-2023-07-15 | C11: ABYA3 | D11: 45122
B12: ABYA3-2023-08-15 | C12: ABYA3 | D12: 45153
B13: ABYA3-2023-09-15 | C13: ABYA3 | D13: 45184
B14: ADHM3-2023-07-15 | C14: ADHM3 | D14: 45122 | I14: Consumo Não-Cíclico
B15: ADHM3-2023-08-15 | C15: ADHM3 | D15: 45153 | I15: Consumo Não-Cíclico
B16: ADHM3-2023-09-15 | C16: ADHM3 | D16: 45184 | I16: Consumo Não-Cíclico
B17: AERI3-2023-07-15 | C17: AERI3 | D17: 45122 | E17: -0.35548701 | F17: -1 | G17: -0.59353536 | H17: -0.80424795 | I17: Indústria
B18: AERI3-2023-08-15 | C18: AERI3 | D18: 45153 | E18: -0.36107576 | F18: -0.52946209 | G18: -0.46324876 | H18: -0.81336283 | I18: Indústria
B19: AERI3-2023-09-15 | C19: AERI3 | D19: 45184 | E19: -0.36107576 | F19: -1 | G19: -1 | H19: -0.8673348 | I19: Indústria
B20: AESB3-2023-07-15 | C20: AESB3 | D20: 45122 | E20: 1 | F20: 1 | G20: 0.77947905 | H20: 0.85918464 | I20: Utilidade Pública
B21: AESB3-2023-08-15 | C21: AESB3 | D21: 45153 | E21: 1 | F21: -1 | G21: -0.1235587 | H21: 0.72912716 | I21: Utilidade Pública
B22: AESB3-2023-09-15 | C22: AESB3 | D22: 45184 | E22: 1 | F22: -0.82464732 | G22: 0.16948464 | H22: 0.80562133 | I22: Utilidade Pública
B23: APPA3-2023-07-15 | C23: APPA3 | D23: 45122
B24: APPA3-2023-08-15 | C24: APPA3 | D24: 45153
B25: APPA3-2023-09-15 | C25: APPA3 | D25: 45184
B26: APPA4-2023-07-15 | C26: APPA4 | D26: 45122
B27: APPA4-2023-08-15 | C27: APPA4 | D27: 45153
B28: APPA4-2023-09-15 | C28: APPA4 | D28: 45184
B29: AVIL3-2023-07-15 | C29: AVIL3 | D29: 45122
B30: AVIL3-2023-08-15 | C30: AVIL3 | D30: 45153
B31: AVIL3-2023-09-15 | C31: AVIL3 | D31: 45184
B32: AVIL4-2023-07-15 | C32: AVIL4 | D32: 45122
B33: AVIL4-2023-08-15 | C33: AVIL4 | D33: 45153
B34: AVIL4-2023-09-15 | C34: AVIL4 | D34: 45184
B35: EALT3-2023-07-15 | C35: EALT3 | D35: 45122 | E35: -0.88629317 | H35: -1 | I35: Indústria
B36: EALT3-2023-08-15 | C36: EALT3 | D36: 45153 | E36: -0.90377081 | H36: -1 | I36: Indústria
B37: EALT3-2023-09-15 | C37: EALT3 | D37: 45184 | E37: -0.90377081 | H37: -1 | I37: Indústria
B38: EALT4-2023-07-15 | C38: EALT4 | D38: 45122 | E38: -0.88629317 | F38: 0.96283406 | G38: 0.27506063 | H38: -1 | I38: Indústria
B39: EALT4-2023-08-15 | C39: EALT4 | D39: 45153 | E39: -0.90377081 | F39: 0.22703582 | G39: 1 | H39: -1 | I39: Indústria
B40: EALT4-2023-09-15 | C40: EALT4 | D40: 45184 | E40: -0.90377081 | F40: -0.32525974 | G40: 0.95491258 | H40: -1 | I40: Indústria
...

Sheet sector_filled_panel
B1: id | C1: tickers | D1: dates | E1: ebit_12m | F1: ir_3m | G1: sharpe | H1: mkt_cap | I1: sector_c1
B2: ABCB11-2023-07-15 | C2: ABCB11 | D2: 45122 | E2: -0.17915164 | F2: 0.49595556 | G2: -0.85425883 | H2: 0.028966442 | I2: Bancos e Serviços Financeiros
B3: ABCB11-2023-08-15 | C3: ABCB11 | D3: 45153 | E3: 0.31731133 | F3: 1 | G3: -0.36537734 | H3: 0.096020562 | I3: Bancos e Serviços Financeiros
B4: ABCB11-2023-09-15 | C4: ABCB11 | D4: 45184 | E4: 1 | F4: 1 | G4: 1 | H4: 0.19436808 | I4: Bancos e Serviços Financeiros
B5: ABCB3-2023-07-15 | C5: ABCB3 | D5: 45122 | E5: -0.17915164 | F5: 0.49595556 | G5: -0.85425883 | H5: 0.028966442 | I5: Bancos e Serviços Financeiros
B6: ABCB3-2023-08-15 | C6: ABCB3 | D6: 45153 | E6: 0.31731133 | F6: 1 | G6: -0.36537734 | H6: 0.096020562 | I6: Bancos e Serviços Financeiros
B7: ABCB3-2023-09-15 | C7: ABCB3 | D7: 45184 | E7: 1 | F7: 1 | G7: 1 | H7: 0.19436808 | I7: Bancos e Serviços Financeiros
B8: ABCB4-2023-07-15 | C8: ABCB4 | D8: 45122 | E8: -0.17915164 | F8: 0.49595556 | G8: -0.85425883 | H8: 0.028966442 | I8: Bancos e Serviços Financeiros
B9: ABCB4-2023-08-15 | C9: ABCB4 | D9: 45153 | E9: 0.31731133 | F9: 1 | G9: -0.36537734 | H9: 0.096020562 | I9: Bancos e Serviços Financeiros
B10: ABCB4-2023-09-15 | C10: ABCB4 | D10: 45184 | E10: 1 | F10: 1 | G10: 1 | H10: 0.19436808 | I10: Bancos e Serviços Financeiros
B11: ABYA3-2023-07-15 | C11: ABYA3 | D11: 45122
B12: ABYA3-2023-08-15 | C12: ABYA3 | D12: 45153
B13: ABYA3-2023-09-15 | C13: ABYA3 | D13: 45184
B14: ADHM3-2023-07-15 | C14: ADHM3 | D14: 45122 | I14: Consumo Não-Cíclico
B15: ADHM3-2023-08-15 | C15: ADHM3 | D15: 45153 | I15: Consumo Não-Cíclico
B16: ADHM3-2023-09-15 | C16: ADHM3 | D16: 45184 | I16: Consumo Não-Cíclico
B17: AERI3-2023-07-15 | C17: AERI3 | D17: 45122 | E17: -0.35548701 | F17: -1 | G17: -0.59353536 | H17: -0.80424795 | I17: Indústria
B18: AERI3-2023-08-15 | C18: AERI3 | D18: 45153 | E18: -0.36107576 | F18: -0.52946209 | G18: -0.46324876 | H18: -0.81336283 | I18: Indústria
B19: AERI3-2023-09-15 | C19: AERI3 | D19: 45184 | E19: -0.36107576 | F19: -1 | G19: -1 | H19: -0.8673348 | I19: Indústria
B20: AESB3-2023-07-15 | C20: AESB3 | D20: 45122 | E20: 1 | F20: 1 | G20: 0.77947905 | H20: 0.85918464 | I20: Utilidade Pública
B21: AESB3-2023-08-15 | C21: AESB3 | D21: 45153 | E21: 1 | F21: -1 | G21: -0.1235587 | H21: 0.72912716 | I21: Utilidade Pública
B22: AESB3-2023-09-15 | C22: AESB3 | D22: 45184 | E22: 1 | F22: -0.82464732 | G22: 0.16948464 | H22: 0.80562133 | I22: Utilidade Pública
B23: APPA3-2023-07-15 | C23: APPA3 | D23: 45122
